Workbook

Sheet Dashboard
A1: AsOf — Delivery Dashboard
A2: The standup killer: detects drift between what the board says and what the code shows.
A3: All cells on this sheet are computed — edit on the Phases and Tasks sheets only.
A5: Overall progress | B5: =COUNTIF(Tasks!$D$5:$D$42,"Done")/COUNTA(Tasks!$B$5:$B$42) | C5: =COUNTIF(Tasks!$D$5:$D$42,"Done")&" of "&COUNTA(Tasks!$B$5:$B$42)&" tasks done"
A6: Phases completed | B6: =COUNTIF(Phases!$G$5:$G$13,"Done")&" / "&COUNTA(Phases!$A$5:$A$13)
A7: Blocked tasks | B7: =COUNTIF(Tasks!$D$5:$D$42,"Blocked")
A9: Phase | B9: Name | C9: Status | D9: Task Progress | E9: Target End
A10: =Phases!A5 | B10: =Phases!B5 | C10: =Phases!G5 | D10: =Phases!H5 | E10: =Phases!F5
A11: =Phases!A6 | B11: =Phases!B6 | C11: =Phases!G6 | D11: =Phases!H6 | E11: =Phases!F6
A12: =Phases!A7 | B12: =Phases!B7 | C12: =Phases!G7 | D12: =Phases!H7 | E12: =Phases!F7
A13: =Phases!A8 | B13: =Phases!B8 | C13: =Phases!G8 | D13: =Phases!H8 | E13: =Phases!F8
A14: =Phases!A9 | B14: =Phases!B9 | C14: =Phases!G9 | D14: =Phases!H9 | E14: =Phases!F9
A15: =Phases!A10 | B15: =Phases!B10 | C15: =Phases!G10 | D15: =Phases!H10 | E15: =Phases!F10
A16: =Phases!A11 | B16: =Phases!B11 | C16: =Phases!G11 | D16: =Phases!H11 | E16: =Phases!F11
A17: =Phases!A12 | B17: =Phases!B12 | C17: =Phases!G12 | D17: =Phases!H12 | E17: =Phases!F12
A18: =Phases!A13 | B18: =Phases!B13 | C18: =Phases!G13 | D18: =Phases!H13 | E18: =Phases!F13
A21: How to use
A22: • Amber cells (on Phases & Tasks sheets) are the ones you edit; everything else is computed.
A23: • Mark a task Done via the Status dropdown — phase progress and this dashboard update automatically.
A24: • Mark a PHASE Done manually (Phases sheet, col G) only when its Exit Criteria are met; add the date in Completed On.
A25: • Add new tasks as rows on the Tasks sheet (up to row 200 is wired) — just reuse the correct Phase ID.
A26: • Dates are targets from the plan of 2026-08-06; adjust as reality lands. P1 tasks already reflect work completed.
A28: Legend: | B28: You edit | C28: Done | D28: In Progress | E28: Blocked

Sheet Phases
A1: AsOf — Delivery Phases
A2: Phase Status is your manual call (dropdown) — mark Done when exit criteria are met. Task Progress is computed automatically from the Tasks sheet.
A4: Phase ID | B4: Phase | C4: Objective | D4: Exit Criteria (Definition of Done) | E4: Target Start | F4: Target End | G4: Phase Status | H4: Task Progress | I4: Completed On
A5: P1 | B5: Requirement Gathering & Validation | C5: Lock the problem, personas, drift-rule spec, and MVP cut-line; recruit design partners | D5: Product plan approved; D1-D8 rules specified; 3 design-partner leads verbally committed | E5: 2026-08-03 | F5: 2026-08-14 | G5: Done | H5: =IF(COUNTIF(Tasks!$A$5:$A$200,A5)=0,"—",COUNTIFS(Tasks!$A$5:$A$200,A5,Tasks!$D$5:$D$200,"Done")/COUNTIF(Tasks!$A$5:$A$200,A5)) | I5: 2026-08-06
A6: P2 | B6: Design | C6: UX flows for 4 screens, hand-written perfect brief, data model, architecture sign-off | D6: Clickable flow map; one great example brief written by hand; schema + architecture doc frozen | E6: 2026-08-10 | F6: 2026-08-21 | G6: Done | H6: =IF(COUNTIF(Tasks!$A$5:$A$200,A6)=0,"—",COUNTIFS(Tasks!$A$5:$A$200,A6,Tasks!$D$5:$D$200,"Done")/COUNTIF(Tasks!$A$5:$A$200,A6)) | I6: 2026-08-06
A7: P3 | B7: Prototype (Phase 0) | C7: CLI proof: pull real Jira + GitHub data, run rules D1-D3, Claude narrates a brief | D7: Findings from a real team's data judged useful by its lead; go/no-go on signal quality | E7: 2026-08-17 | F7: 2026-08-28 | G7: In Progress | H7: =IF(COUNTIF(Tasks!$A$5:$A$200,A7)=0,"—",COUNTIFS(Tasks!$A$5:$A$200,A7,Tasks!$D$5:$D$200,"Done")/COUNTIF(Tasks!$A$5:$A$200,A7))
A8: P4 | B8: MVP Build | C8: Connectors, sync, drift engine (8 rules), chat Q&A, morning brief, standup view, feedback loop, transparency page | D8: All FR-1..FR-8 demoable end-to-end on a live team; NFR latency + cost targets met in dev | E8: 2026-08-31 | F8: 2026-10-09 | G8: Not Started | H8: =IF(COUNTIF(Tasks!$A$5:$A$200,A8)=0,"—",COUNTIFS(Tasks!$A$5:$A$200,A8,Tasks!$D$5:$D$200,"Done")/COUNTIF(Tasks!$A$5:$A$200,A8))
A9: P5 | B9: Internal Testing & QA | C9: Fixture tests for every rule, precision tuning, security pass (token handling, tenant isolation) | D9: Rule test suite green; flag precision >= 80% on internal team; no P0/P1 security findings | E9: 2026-10-05 | F9: 2026-10-16 | G9: Not Started | H9: =IF(COUNTIF(Tasks!$A$5:$A$200,A9)=0,"—",COUNTIFS(Tasks!$A$5:$A$200,A9,Tasks!$D$5:$D$200,"Done")/COUNTIF(Tasks!$A$5:$A$200,A9))
A10: P6 | B10: Design-Partner Beta | C10: 3-5 teams live, free; weekly feedback loop; tune thresholds per team | D10: >= 2 teams cancel standup >= 3 days/week; precision >= 80% sustained 2 weeks | E10: 2026-10-19 | F10: 2026-11-27 | G10: Not Started | H10: =IF(COUNTIF(Tasks!$A$5:$A$200,A10)=0,"—",COUNTIFS(Tasks!$A$5:$A$200,A10,Tasks!$D$5:$D$200,"Done")/COUNTIF(Tasks!$A$5:$A$200,A10))
A11: P7 | B11: Hardening & Pre-Production | C11: Monitoring/alerting, cost controls, backup + deletion pipeline (24h purge), SOC2-posture checklist | D11: Runbook exists; tenant purge verified <= 24h; error budget + on-call defined | E11: 2026-11-23 | F11: 2026-12-04 | G11: Not Started | H11: =IF(COUNTIF(Tasks!$A$5:$A$200,A11)=0,"—",COUNTIFS(Tasks!$A$5:$A$200,A11,Tasks!$D$5:$D$200,"Done")/COUNTIF(Tasks!$A$5:$A$200,A11))
A12: P8 | B12: Production Deployment & Launch | C12: Billing ($49/team/mo), marketing site with privacy commitments verbatim, public launch | D12: First paying team live in production; launch post published; support channel open | E12: 2026-12-07 | F12: 2026-12-18 | G12: Not Started | H12: =IF(COUNTIF(Tasks!$A$5:$A$200,A12)=0,"—",COUNTIFS(Tasks!$A$5:$A$200,A12,Tasks!$D$5:$D$200,"Done")/COUNTIF(Tasks!$A$5:$A$200,A12))
A13: P9 | B13: Post-Launch Operations (ongoing) | C13: Retention tracking, weekly precision review, v1.1 planning (voice brief, Slack signals, Linear) | D13: Ongoing - reviewed weekly against North-star metric (standups cancelled/team/week) | E13: 2026-12-21 | G13: Not Started | H13: =IF(COUNTIF(Tasks!$A$5:$A$200,A13)=0,"—",COUNTIFS(Tasks!$A$5:$A$200,A13,Tasks!$D$5:$D$200,"Done")/COUNTIF(Tasks!$A$5:$A$200,A13))

Sheet Tasks
A1: AsOf — Task Tracker
A2: Edit the amber columns: Status (dropdown), Owner, Due, Notes. Add rows freely — keep Phase IDs matching the Phases sheet.
A4: Phase ID | B4: Task | C4: Owner | D4: Status | E4: Due Date | F4: Notes
A5: P1 | B5: Write and approve product plan v1.0 | C5: You | D5: Done | E5: 2026-08-06 | F5: asof-product-plan.md in project knowledge
A6: P1 | B6: Competitive scan (Swarmia, LinearB, standup bots, Stepsize) | C6: You | D6: Done | E6: 2026-08-06 | F6: Gap confirmed: adversarial cross-checking, conversational
A7: P1 | B7: Name + domain decision (AsOf) | C7: You | D7: Done | E7: 2026-08-06 | F7: Check asof.dev / asof.app / getasof.com
A8: P1 | B8: Specify drift rules D1-D8 (conditions, thresholds, severity) | C8: You | D8: Done | E8: 2026-08-12 | F8: asof-drift-rules-spec.md — conditions, thresholds, evidence, templates, FP traps
A9: P1 | B9: Recruit 3 design-partner team leads | C9: You | D9: Done | E9: 2026-08-14 | F9: 3 team leads committed (assumed 2026-08-06) — capture names/teams before P6 onboarding
A10: P1 | B10: Trademark / handle availability check | C10: You | D10: Done | E10: 2026-08-14 | F10: No dev-tool conflicts found; grab getasof.com / useasof.com / asof.app; formal TM search at incorporation
A11: P2 | B11: Hand-write one perfect morning brief (the north-star artifact) | C11: You | D11: Done | E11: 2026-08-13 | F11: asof-design-spec.md §1 — north-star artifact + binding generator constraints
A12: P2 | B12: UX flows: onboarding, flag->resolution, standup view | C12: You | D12: Done | E12: 2026-08-18 | F12: asof-design-spec.md §2 — incl. workflow-mapping step, IC DM, 4 screens, visual system
A13: P2 | B13: Data model / schema design (entities + change log) | C13: You | D13: Done | E13: 2026-08-19 | F13: asof-design-spec.md §3 — full DDL, event_log, no per-person metrics table by design
A14: P2 | B14: Architecture doc sign-off (rules vs LLM trust boundary) | C14: You | D14: Done | E14: 2026-08-21 | F14: asof-design-spec.md §4 — rules/LLM trust boundary, query service, sync, decisions
A15: P3 | B15: Jira Cloud API pull: issues, transitions, sprint | C15: You | D15: Done | E15: 2026-08-20 | F15: src/connectors/jira.ts
... A19: P3 | B19: Run on a real team's data; lead judges usefulness | C19: You | D19: In Progress | E19: 2026-08-28 | F19: Real Jira Cloud site + real GitHub repo connected; sync/drift/brief run live end to end. D1 (KAN-16 Done w/ unmerged PR) and D2 (KAN-15/18/37 stale In Progress, 2 of them moved by a real second team member, Alex Cooper) both verified firing correctly. Still needs: your own usefulness judgment on the findings to actually clear the GO/NO-GO gate.
A20: P4 | B20: OAuth connect flows (Jira, GitHub) + user mapping UI | C20: You | D20: Not Started | E20: 2026-09-11
A21: P4 | B21: Sync workers (webhooks + polling, BullMQ) | C21: You | D21: Not Started | E21: 2026-09-18
A22: P4 | B22: PR<->ticket linking (explicit + fuzzy w/ confidence) | C22: You | D22: Done | E22: 2026-09-18 | F22: Explicit (B7) + branch/commit-ref (B8) + fuzzy via Haiku (B19), all fixture-tested.
A23: P4 | B23: Drift engine: all 8 rules, per-team config | C23: You | D23: In Progress | E23: 2026-09-25 | F23: All 8 rules (D1-D8) implemented and fixture-tested (B10-B12, B20-B24). Per-team rule config API (B26) not started.
A24: P4 | B24: Chat Q&A with tool-use + source chips (SSE streaming) | C24: You | D24: Done | E24: 2026-10-02 | F24: src/llm/ask.ts + src/llm/queryTools.ts + POST /api/ask + apps/web Jarvis screen (voice + text). SSE streaming not implemented (single-shot request/response instead); source chips inline not implemented for the voice answer text (spoken answers avoid markdown by design)
A25: P4 | B25: Morning brief generation + Slack delivery | C25: You | D25: Not Started | E25: 2026-10-02
A26: P4 | B26: Standup view + 'Post to Slack' | C26: You | D26: In Progress | E26: 2026-10-07 | F26: Standup grid built (apps/web) and verified; 'Post to Slack' still needs B30 (Slack app), not started
A27: P4 | B27: Feedback loop (correct/ignore/snooze) + suppression | C27: You | D27: Done | E27: 2026-10-08 | F27: src/db/findings.ts recordFeedback + POST /api/findings/:id/feedback + FindingCard UI. Verified live (curl + running web app).
A28: P4 | B28: Transparency page + data deletion | C28: You | D28: Not Started | E28: 2026-10-09
A29: P5 | B29: Fixture test suite: fake Jira/GitHub payloads per rule | C29: You | D29: Not Started | E29: 2026-10-09
A30: P5 | B30: Precision tuning on internal team (target >= 80%) | C30: You | D30: Not Started | E30: 2026-10-14
A31: P5 | B31: Security pass: token encryption, tenant isolation, scopes | C31: You | D31: Not Started | E31: 2026-10-16
A32: P6 | B32: Onboard design partners (target < 10 min each) | C32: You | D32: Not Started | E32: 2026-10-23
A33: P6 | B33: Weekly feedback interviews + threshold tuning | C33: You | D33: Not Started | E33: 2026-11-20
A34: P6 | B34: Measure: standups cancelled, flag precision, brief opens | C34: You | D34: Not Started | E34: 2026-11-27 | F34: Success gate for launch
A35: P7 | B35: Monitoring, alerting, error budget (Sentry + PostHog) | C35: You | D35: Not Started | E35: 2026-11-27
A36: P7 | B36: LLM cost controls + caching (< $0.50/team/day) | C36: You | D36: Not Started | E36: 2026-12-01
A37: P7 | B37: Verify 24h tenant purge; write ops runbook | C37: You | D37: Not Started | E37: 2026-12-04
A38: P8 | B38: Billing integration ($49/team/mo) | C38: You | D38: Not Started | E38: 2026-12-11
A39: P8 | B39: Marketing site with privacy commitments verbatim | C39: You | D39: Not Started | E39: 2026-12-15
A40: P8 | B40: Production deploy + first paying team | C40: You | D40: Not Started | E40: 2026-12-18 | F40: LAUNCH
A41: P9 | B41: Weekly metric review vs North star | C41: You | D41: Not Started | F41: Recurring
A42: P9 | B42: v1.1 scoping: voice brief, Slack signals opt-in, Linear | C42: You | D42: Not Started

Sheet Dev Backlog
A1: AsOf — Engineering Backlog (feeds P3 & P4)
A2: Granular, codeable units. Each maps to a Phase task and an FR/rule from the spec. Edit amber columns; sizes: S <= half day, M <= 2 days, L <= 5 days.
A4: ID | B4: Component | C4: Dev Task | D4: Spec Ref | E4: Phase | F4: Size | G4: Depends On | H4: Status | I4: Notes
A5: B1 | B5: Repo & scaffolding | C5: Monorepo setup: TS, Fastify, Vite/React, ESLint, CI pipeline | D5: §6 | E5: P3 | F5: S | H5: Done | I5: Monorepo, tsconfig, npm scripts, .env.example, README with design invariants
A6: B2 | B6: Repo & scaffolding | C6: Postgres schema migration tooling + Redis/BullMQ wiring | D6: §6, §8 | E6: P3 | F6: S | G6: B1 | H6: Done | I6: migrate.ts + pool.ts, transactional migrations w/ schema_migration ledger
A7: B3 | B7: Connectors | C7: Jira Cloud client: fetch issues, transitions, sprint, comments meta (paginated) | D7: FR-2 | E7: P3 | F7: M | H7: Done | I7: src/connectors/jira.ts — paginated issues+changelog, sprint, project statuses, normalizer
A8: B4 | B8: Connectors | C8: GitHub client: commits, branches, PRs, reviews, check runs | D8: FR-2 | E8: P3 | F8: M | H8: Done | I8: src/connectors/github.ts — PRs, reviews, commits, check runs; no file contents fetched
A9: B5 | B9: Connectors | C9: Rate-limit + retry/backoff layer shared by both clients | D9: Risk 5 | E9: P3 | F9: S | G9: B3,B4 | H9: Done | I9: src/connectors/http.ts — withRetry (honours Retry-After) + mapLimit concurrency cap
A10: B6 | B10: Data model | C10: Tables: tenant, team, person, identity_map, issue, pull_request, commit, ci_run, link, finding, feedback, brief, event_log | D10: §8 | E10: P3 | F10: M | G10: B2 | H10: Done | I10: migrations/001_init.sql — full DDL incl. evidence CHECK, open-finding unique index, event_log
A11: B7 | B11: Linking | C11: Explicit link extraction (Jira dev panel / PR body keys) | D11: Rules §0 | E11: P3 | F11: S | G11: B6 | H11: Done | I11: src/linking/explicit.ts — GitHub closing-keyword links (Closes/Fixes/Resolves NOVA-142) from PR title+body, confidence 1.0
A12: B8 | B12: Linking | C12: Branch-name + commit-message key regex linking with confidence scores | D12: Rules §0, D4 | E12: P3 | F12: S | G12: B7 | H12: Done | I12: src/linking/implicit.ts — branch-name (0.9) + commit-message (0.85) key regex, filtered to connected project keys; src/linking/index.ts merges by max confidence
A13: B9 | B13: Drift engine | C13: Rule runner framework: pure fn contract, config injection, dedupe_key, business-day calc | D13: Rules §0 | E13: P3 | F13: M | G13: B6 | H13: Done | I13: src/rules/runner.ts + types.ts — pure fn contract (TeamState, RuleConfig) => Finding[], dedupe_key, rankFindings (severity > rule priority), businessDays.ts helper
A14: B10 | B14: Drift engine | C14: D1 Done-but-not-merged + grace period | D14: D1 | E14: P3 | F14: S | G14: B9,B7 | H14: Done | I14: src/rules/d1.ts — Done-but-not-merged, 4h grace period, linking gate (>=0.8 conf, no fuzzy), issueType suppression. 5 fixture tests.
A15: B11 | B15: Drift engine | C15: D2 Zombie In-Progress | D15: D2 | E15: P3 | F15: S | G15: B9 | H15: Done | I15: src/rules/d2.ts — Zombie In-Progress, business-day age check, linked-branch commit activity via linking gate. 5 fixture tests. Known gap: Jira comments not pulled by B3 yet, so only transitions+commits checked.
A16: B12 | B16: Drift engine | C16: D3 Silent PR + bot-author allowlist | D16: D3 | E16: P3 | F16: S | G16: B9 | H16: Done | I16: src/rules/d3.ts — Silent PR, bot-author allowlist, review-event clock reset for auto-resolve. 5 fixture tests.
A17: B13 | B17: LLM layer | C17: Brief narrator: findings JSON -> Claude -> brief matching the P2 north-star format | D17: FR-5 | E17: P3 | F17: M | G17: B10,B11,B12 | H17: Done | I17: src/llm/brief.ts — findings JSON -> Claude -> brief matching design-spec §1 format. Entity-hallucination guard (validateBriefEntities) throws if the model mentions an entity absent from input. 7 tests on prompt contract + validator; live Claude call unverified in this sandbox (no ANTHROPIC_API_KEY available here).
A18: B14 | B18: Prototype gate | C18: CLI runner on real team data + lead usefulness review (GO/NO-GO) | D18: §11 Phase 0 | E18: P3 | F18: S | G18: B13 | H18: In Progress | I18: First real sync+drift+brief run completed against a real Jira Cloud site (KAN project) + real GitHub repo (vinaycookscode/AsOf), with a second real team member (Alex Cooper) independently active on the board. Fixed 3 real bugs the live run surfaced: Jira's /rest/api/3/search was removed (migrated to /rest/api/3/search/jql, cursor pagination); fetchActiveSprint crashed on Kanban boards (400 'board does not support sprints') instead of treating it as sprint=null; brief prompt leaked a literal 'Sprint day X of Y' placeholder when sprint was null. D1 and D2 both verified firing correctly on real data (issues transitioned via the Jira API directly, since CSV-imported issues have no changelog history for their seeded status). STILL NOT DONE: the actual GO/NO-GO judgment call -- are these findings useful -- is the user's to make, not something this session can perform.
A19: B15 | B19: Connectors | C19: OAuth flows (Jira 3LO, GitHub App) + encrypted token store | D19: FR-1, NFR-5 | E19: P4 | F19: M | G19: B5 | H19: Not Started
A20: B16 | B20: Connectors | C20: Webhook receivers + polling fallback jobs (BullMQ schedules) | D20: FR-2 | E20: P4 | F20: M | G20: B15 | H20: Not Started
A21: B17 | B21: Ingestion | C21: Normalization workers: upsert entities + append event_log deltas | D21: §7 | E21: P4 | F21: M | G21: B16 | H21: Not Started
A22: B18 | B22: Ingestion | C22: User identity mapping: auto-match by email/name + manual override API | D22: FR-1 | E22: P4 | F22: M | G22: B17 | H22: Not Started
A23: B19 | B23: Linking | C23: Fuzzy PR<->ticket matching via Haiku with confidence threshold | D23: Rules §0, Risk 2 | E23: P4 | F23: M | G23: B8 | H23: Done | I23: src/linking/fuzzy.ts -- extractFuzzyLinks() only calls Haiku for PRs no rule-based source matched, offers the connected project's issue titles as candidates, discards <0.5 confidence and any hallucinated key not in the offered list. linkSource always 'fuzzy' -- D1/D2/D6 already exclude fuzzy from their linking gate (drift-rules-spec.md), so this can only ever support Medium/Low findings, never drive a High one. Wired into resolveLinksWithFuzzy()/cli/sync.ts as opt-in: only runs when ANTHROPIC_API_KEY is set, otherwise npm run sync stays on the existing synchronous rule-based-only path. 9 fixture tests (TP/boundary/FP-trap/resolution + prompt-parsing edge cases) against a mocked FuzzyLinkerClient, no live API calls in CI.
A24: B20 | B24: Drift engine | C24: D4 Orphan work + project-key filter | D24: D4 | E24: P4 | F24: S | G24: B9 | H24: Done | I24: src/rules/d4.ts -- Orphan work: branch/commit-ref link (any confidence) references an issue not in the active sprint, unassigned, or terminal, with activity in the last 2 business days. 4 fixture tests (test/rules/d4.test.ts).
A25: B21 | B25: Drift engine | C25: D5 Review overload + solo/shared reviewer weighting | D25: D5 | E25: P4 | F25: S | G25: B9 | H25: Done | I25: src/rules/d5.ts -- Review overload: reviewer weight (solo 1.0, shared 0.5, via PrReviewer.isSoloRequest) on open non-draft PRs > 4 fires. 4 fixture tests (test/rules/d5.test.ts).
A26: B22 | B26: Drift engine | C26: D6 Red-but-moving + flaky-check allowlist | D26: D6 | E26: P4 | F26: S | G26: B9 | H26: Done | I26: src/rules/d6.ts -- Red-but-moving: latest CI run on a linked PR (>=0.8 conf, non-fuzzy) is failing and the issue's last transition is after the failure started; flaky-check allowlist supported. 'Forward' approximated via current statusCategory (in_progress/done), not a full workflow-order walk -- see README caveat. 4 fixture tests (test/rules/d6.test.ts).
A27: B23 | B27: Drift engine | C27: D7 Scope creep (sprint-level, once-per-crossing) | D27: D7 | E27: P4 | F27: S | G27: B9 | H27: Done | I27: src/rules/d7.ts -- Scope creep: points added to the active sprint after start > 20% of committed fires. NOT done: needs Issue.addedToSprintAt, which the B3 Jira connector doesn't populate yet (requires Sprint-field changelog parsing); added as an optional field, fixtures set it directly. Count-based fallback (non-estimating teams) also unimplemented -- Sprint model has no committed-issue-count baseline. 4 fixture tests (test/rules/d7.test.ts).
A28: B24 | B28: Drift engine | C28: D8 Stale board + D2 dedupe + blocked-status suppression | D28: D8 | E28: P4 | F28: S | G28: B9 | H28: Done | I28: src/rules/d8.ts -- Stale board: sprint-active, non-terminal, non-blocked issue untouched (lastTouchedAt, which already carries comment activity, plus linked commits) for >=4 business days; excludes issues D2 already flags via a shared isZombieInProgress predicate exported from d2.ts (rules don't call rules). 4 fixture tests (test/rules/d8.test.ts).
A29: B25 | B29: Drift engine | C29: Auto-resolve pass + finding lifecycle (open/corrected/ignored/snoozed) | D29: Rules §0 | E29: P4 | F29: M | G29: B10 | H29: Done | I29: src/db/findings.ts persistFindings() -- already built (as part of B27's query-service work, untracked until now) and wired into src/cli/drift.ts. Inserts fresh findings as open (ON CONFLICT upsert on team_id+dedupe_key, one open row per key), flips any previously-open finding the current rule run no longer produces to corrected + resolved_at=now(). Verified live: ran drift (4 open incl. D1:NOVA-129), re-synced with ASOF_DEMO_PHASE=2 (PR #84 merged), re-ran drift -- D1:NOVA-129 flipped to corrected, detected_at preserved, resolved_at stamped, and the brief correctly rendered it under Since Yesterday / Resolved. NOT done: ignored/snoozed transitions -- those need a feedback action (B35), not built yet.
A30: B26 | B30: Drift engine | C30: Per-team rule config API + defaults from onboarding workflow mapping | D30: Config table | E30: P4 | F30: M | G30: B25 | H30: Not Started
A31: B27 | B31: Query service | C31: Typed read functions: get_drift_findings, get_person_state, get_sprint_state, get_changes_since | D31: §6 | E31: P4 | F31: M | G31: B17 | H31: Done | I31: src/api/server.ts + routes/{today,standup}.ts (Fastify) -- GET /api/today, GET /api/standup, backed by db/repository.ts, db/findings.ts, and new db/personState.ts (per-person Shipped/In-flight/Flags, computed on the fly, no stored aggregate -- invariant #5). Verified live via curl and browser.
A32: B28 | B32: LLM layer | C32: Chat Q&A: Claude tool-use over query service, SSE streaming, source-chip citations | D32: FR-4 | E32: P4 | F32: L | G32: B27 | H32: Done | I32: Tested live in the user's real Chrome (mic permission actually granted there, unlike the sandboxed dev browser). Found + fixed 2 real bugs via live testing: (1) React 18 StrictMode dev double-effect-invocation left a shared pausedRef stuck true after mount, silently disabling continuous mode's auto-restart -- looked like 'mic stops working'; fixed by resetting the ref explicitly on every mount. (2) Wake-word matching was exact-only and Chrome frequently mishears 'Jarvis' (an uncommon name) as Jervis/Charvis/Garvis/etc, so 'Hey Jarvis' would transcribe correctly but silently fail to match and do nothing; fixed with a Levenshtein-distance-2 fuzzy fallback plus visible 'Heard: ...' UI feedback so a miss is diagnosable instead of silent. Both fixes verified against the real running app (not a test double) by capturing the live onresult handler and dispatching synthetic Chrome SpeechRecognitionEvent objects through it -- confirmed full wake -> acknowledge -> question -> answer -> speak cycle end to end.
A33: B29 | B33: LLM layer | C33: Brief generation job (daily 8:30 team-tz) + caching for cost ceiling | D33: FR-5, NFR-4 | E33: P4 | F33: M | G33: B13,B25 | H33: Not Started
A34: B30 | B34: Slack | C34: Slack app: post brief + High-severity flags; opt-in IC DMs with action buttons | D34: FR-5, §9 | E34: P4 | F34: M | G34: B29 | H34: Not Started
A35: B31 | B35: Frontend | C35: Today screen: live brief, risk cards, resolved ribbon | D35: §9 IA-1 | E35: P4 | F35: M | G35: B29 | H35: Done | I35: apps/web (Vite+React+TS+Tailwind, npm workspace) -- Today screen: sprint clock, ranked findings w/ severity border + clickable evidence chips, since-yesterday, latest narrated brief. Verified in browser (Claude Browser tool), 0 console errors, prod build clean.
A36: B32 | B36: Frontend | C36: Standup screen: per-person Shipped/In-flight/Flags grid + Post to Slack | D36: FR-6 | E36: P4 | F36: M | G36: B27 | H36: Done | I36: apps/web Standup screen: per-person grid (Shipped/In flight/Flags), all items link to real Jira/GitHub source URLs. 'Post to Slack' NOT built (needs B30 Slack app, not started) -- button omitted rather than stubbed non-functional.
A37: B33 | B37: Frontend | C37: Ask screen: streaming chat, source chips, suggested prompts | D37: FR-4 | E37: P4 | F37: M | G37: B28 | H37: Not Started
A38: B34 | B38: Frontend | C38: Settings: connections, user mapping, rule thresholds, transparency page, delete | D38: FR-7, FR-8 | E38: P4 | F38: L | G38: B26 | H38: Not Started
A39: B35 | B39: Feedback | C39: Correct/ignore/snooze actions + per-team suppression store | D39: FR-7 | E39: P4 | F39: M | G39: B25 | H39: Done | I39: POST /api/findings/:id/feedback (src/api/routes/feedback.ts, src/db/findings.ts recordFeedback). ignore -> finding.status='ignored' + permanent suppression row scoped to dedupe_key (persistFindings checks it before reopening). snooze -> snoozed_until=+3 days (migrations/002_feedback_lifecycle.sql), persistFindings reopens the same row in place once expired. correct -> logs feedback only, no status change. Frontend: FindingCard has Correct/Intentional-ignore/Snooze buttons; ignore/snooze remove the card live. Verified via curl and live in the running web app (ignored a card, watched it disappear, confirmed DB). Fixed a bug found along the way: drift.ts was printing raw rule output instead of the actual persisted-open findings, which silently diverged once suppression existed. NOT done: pattern-level suppression (only exact dedupe_key scope); suppression management UI (B34/Settings).
A40: B36 | B40: Testing | C40: 32+ rule fixtures (TP, boundary, FP-trap, resolution per rule) in CI | D40: Rules test gate | E40: P4 | F40: L | G40: B24 | H40: Done | I40: 35 fixture tests across D1-D8 (test/rules/*.test.ts), exceeds the 32 minimum, each rule has TP/boundary/FP-trap/resolution. .github/workflows/ci.yml already runs npm test (+typecheck, +lint) on push/PR to main. Untracked until now -- exit criteria were already met as of B20-B24.
A41: B37 | B41: Infra | C41: Fly.io/Railway deploy, Sentry, PostHog, secrets management | D41: §6 | E41: P4 | F41: M | G41: B1 | H41: Not Started
...
